Workbook

Sheet LIVE Real Time Control
D2: ATEQ Output Addresses | I2: PLC INPUT from ATEQ | J2: ENTER PLC Starting Address in GREEN AREA Below | O2: ENTER Binary Value ONLY in GREEN AREAS | P2: ENTER HEX Value ONLY in GREEN AREAS | Z2: ATEQ Input Address | AE2: PLC OUTPUT to ATEQ | AF2: ENTER PLC Starting Address in GREEN AREA Below | AK2: HEX / Binary | AL2: ENTER HEX Value ONLY in GREEN AREAS | AM2: HEX CMD Word | AN2: HEX CMD Word Swap | AO2: DEC CMD Word | AP2: DEC CMD Word Swap | AQ2: Actual Data Dec | AR2: Actual Data Swap Dec | AS2: Binary | AT2: Cycle Step
D3: Word | F3: Byte | J3: PLC Word INT | L3: BYTE | Q3: Word HEX | R3: HEX Swap | S3: DEC | T3: Swap DEC | U3: Actual Data | V3: Actual Data Swap | Z3: Word | AB3: Byte | AF3: PLC Word INT
D4: Hex | E4: Dec | F4: Hex | G4: Dec | H4: Bits | I4: Description | J4: Hex | K4: Dec | L4: DEC | M4: HEX | N4: Bits | Z4: Hex | AA4: Dec | AB4: Hex | AC4: Dec | AD4: Bits | AE4: ATEQ Commands | AF4: Hex | AG4: Dec | AJ4: Bits | AU4: Chapter 21 page 217/286 in NetworksO manual
B5: Echo Signals | C5: Echo Signals | F5: 00 | G5: =HEX2DEC(F5) -> 0 | H5: 0 | I5: Echo reset | J5: =DEC2HEX(K5,4) -> 03EE | K5: 1006 | L5: =K5 -> 1006 | M5: =DEC2HEX(L5,4) -> 03EE | N5: 0 | O5: 0 | P5: =BIN2HEX(CONCATENATE(O12,O11,O10,O9,O8,O7,O6,O5)) -> 0 | Q5: =CONCATENATE(P5,P13) -> 080 | R5: =CONCATENATE(P13,P5) -> 800 | S5: =MOD(HEX2DEC(Q5)+2^15,2^16)-2^15 -> 128 | T5: =MOD(HEX2DEC(R5)+2^15,2^16)-2^15 -> 2048 | X5: Commands | Y5: =+X5 -> Commands | AB5: =DEC2HEX(AC5) -> 0 | AC5: 0 | AD5: 0 | AE5: Reset (stop the current cycle) | AF5: =DEC2HEX(AG5,4) -> 0858 | AG5: 2136 | AH5: =AG5 -> 2136 | AI5: =DEC2HEX(AH5,4) -> 0858 | AJ5: 0 | AK5: 0 | AL5: =BIN2HEX(CONCATENATE(AK12,AK11,AK10,AK9,AK8,AK7,AK6,AK5)) -> 0 | AM5: =CONCATENATE(AL5,AL13) -> 00 | AN5: =CONCATENATE(AL13,AL5) -> 00 | AO5: =MOD(HEX2DEC(AM5)+2^15,2^16)-2^15 -> 0 | AP5: =MOD(HEX2DEC(AN5)+2^15,2^16)-2^15 -> 0 | AS5: 1 | AT5: 2 | AU5: 2.1.4 PDF Page 223/286 | AV5: Rising edge clears Alarms & Pass/Fail Bits or stops the current cycle
H6: 1 | I6: Echo start | N6: 1 | O6: 0 | AD6: 1 | AE6: Start (Test or Special cycle) | AJ6: 1 | AK6: 0 | AS6: =AS5*10 -> 10 | AT6: 4 | AU6: 2.1.3 PDF Page 222/286 | AV6: Load Program or Special cycle first then set to 1 rising edge to start
H7: 2 | I7: Echo special cycle | N7: 2 | O7: 0 | AD7: 2 | AE7: Load Special Cycle code selected at address 8 & 9 | AJ7: 2 | AK7: 0 | AS7: =AS6*10 -> 100 | AU7: 2.1.5 PDF Page 224/286 | AV7: Set Special Cycle code # at 08-09h first then set byte0-Bit2 =1 to load. See chart 1.2 in manual for special cycle options of the unit type used
H8: 3 | I8: Echo program selection | N8: 3 | O8: 0 | AD8: 3 | AE8: Load Program # selection from 06-07h | AJ8: 3 | AK8: 0 | AS8: =AS7*10 -> 1000 | AT8: 1 | AU8: 2.1.2 PDF Page 221/286 | AV8: Set Program # at 06-07h first then set Byte0-Bit3 =1 to load program # (ATEQ screen is +1, e.g. 06h = 01h (01 = program #2 on ATEQ screen)
H9: 4 | I9: Echo reading of the results FIFO | N9: 4 | O9: 0 | AD9: 4 | AE9: Read the FIFO cycles results | AJ9: 4 | AK9: 0 | AS9: =AS8*10 -> 10000
H10: 5 | I10: Echo reading of the parameters | N10: 5 | O10: 0 | AD10: 5 | AE10: Read of the parameters | AJ10: 5 | AK10: 0 | AS10: =AS9*10 -> 100000 | AT10: 6 | AU10: 2.2 PDF Page 226/286 | AV10: Moves the test parameters in the exchange zone at address 20h see "Read Parameters" Excel tab
H11: 6 | I11: Echo writing of the parameters | N11: 6 | O11: 0 | AD11: 6 | AE11: Write of the parameters | AJ11: 6 | AK11: 0 | AS11: =AS10*10 -> 1000000
H12: 7 | I12: Echo reset of the results FIFO | N12: 7 | O12: 0 | AD12: 7 | AE12: Reset of the results in FIFO | AJ12: 7 | AK12: 0 | AS12: =AS11*10 -> 10000000 | AT12: 3 | AU12: 2.5 PDF Page 229/286 | AV12: Clears FIFO to ensure the data moved into the last results is from the last cycle
C13: Echo Signals | F13: 01 | G13: =HEX2DEC(F13) -> 1 | H13: 0 | I13: Echo reading of the instrument configuration | L13: =L5+1 -> 1007 | M13: =DEC2HEX(L13,4) -> 03EF | N13: 8 | O13: 0 | P13: =BIN2HEX(CONCATENATE(O20,O19,O18,O17,O16,O15,O14,O13)) -> 80 | Y13: =+X5 -> Commands | AB13: =DEC2HEX(AC13) -> 1 | AC13: =AC5+1 -> 1 | AD13: 0 | AE13: Read of the instrument configuration | AH13: =AH5+1 -> 2137 | AI13: =DEC2HEX(AH13,4) -> 0859 | AJ13: 8 | AK13: 0 | AL13: =BIN2HEX(CONCATENATE(AK20,AK19,AK18,AK17,AK16,AK15,AK14,AK13)) -> 0 | AS13: 1
H14: 1 | I14: Echo reading of the general bits | N14: 9 | O14: 0 | AD14: 1 | AE14: Read of the general bits. | AJ14: 9 | AK14: 0 | AS14: =AS13*10 -> 10
H15: 2 | I15: Echo reading of the normal bits | N15: 10 | O15: 0 | AD15: 2 | AE15: Read of the normal bits. | AJ15: 10 | AK15: 0 | AS15: =AS14*10 -> 100
H16: 3 | I16: Echo writing of the general bits | N16: 11 | O16: 0 | AD16: 3 | AE16: Write of the general bits. | AJ16: 11 | AK16: 0 | AS16: =AS15*10 -> 1000
H17: 4 | I17: Echo writing of the normal bits | N17: 12 | O17: 0 | AD17: 4 | AE17: Write of the normal bits. | AJ17: 12 | AK17: 0 | AS17: =AS16*10 -> 10000
H18: 5 | I18: Echo reading of the program personalisation | N18: 13 | O18: 0 | AD18: 5 | AE18: Read of the program personalisation | AJ18: 13 | AK18: 0 | AS18: =AS17*10 -> 100000
H19: 6 | I19: Echo writing of the program personalisation | N19: 14 | O19: 0 | AD19: 6 | AE19: Write of the program personalisation. | AJ19: 14 | AK19: 0 | AS19: =AS18*10 -> 1000000
H20: 7 | I20: Echo writing Last Result | N20: 15 | O20: 1 | AD20: 7 | AE20: Load Last result pressure and leak data to address 20h | AJ20: 15 | AK20: 0 | AS20: =AS19*10 -> 10000000 | AT20: 5 | AU20: 2.4 PDF Page 228/286 | AV20: Move the Last Results to the exchange zone at address 20h see "Last Results" Excel tab
B21: Error Code | C21: =+B21 -> Error Code | F21: 02 | G21: =HEX2DEC(F21) -> 2 | H21: 0 | I21: Reset error | J21: =DEC2HEX(K21,4) -> 03EF | K21: =+K5+1 -> 1007 | L21: =L13+1 -> 1008 | M21: =DEC2HEX(L21,4) -> 03F0 | N21: 0 | O21: 0 | P21: =BIN2HEX(CONCATENATE(O28,O27,O26,O25,O24,O23,O22,O21)) -> 0 | Q21: =CONCATENATE(P21,P29) -> 00 | R21: =CONCATENATE(P29,P21) -> 00 | S21: =MOD(HEX2DEC(Q21)+2^15,2^16)-2^15 -> 0 | T21: =MOD(HEX2DEC(R21)+2^15,2^16)-2^15 -> 0 | U21: PLC may or may not see Byte 2 & 3 as FF FF while command is in progress | X21: Commands | Y21: =+X21 -> Commands | AB21: =DEC2HEX(AC21) -> 2 | AC21: =AC13+1 -> 2 | AD21: 0 | AE21: NOT USED | AF21: =DEC2HEX(AG21,4) -> 0859 | AG21: =+AG5+1 -> 2137 | AH21: =AH13+1 -> 2138 | AI21: =DEC2HEX(AH21,4) -> 085A | AJ21: 0
H22: 1 | I22: Start error | N22: 1 | O22: 0 | AB22: =DEC2HEX(AC22) -> 3 | AC22: =AC21+1 -> 3 | AD22: 15 | AE22: NOT USED | AH22: =AH21+1 -> 2139 | AI22: =DEC2HEX(AH22,4) -> 085B | AJ22: 15
H23: 2 | I23: Special cycle error | N23: 2 | O23: 0 | X23: Commands | Y23: =+X23 -> Commands | AB23: =DEC2HEX(AC23) -> 4 | AC23: =AC22+1 -> 4 | AD23: 0 | AE23: NOT Typically USED Select ATEQ "Head" to send commands Only if multiple heads are connected together via RS485 with an ATEQ C540 central controller Address 04h: Number of the targeted module (C540) selection of the head connected to the C540 central. Address 05h = 0 | AF23: =DEC2HEX(AG23,4) -> 085A | AG23: =+AG21+1 -> 2138 | AH23: =AH22+1 -> 2140 | AI23: =DEC2HEX(AH23,4) -> 085C | AJ23: 0 | AK23: Not Typically Used
H24: 3 | I24: Program selection error | N24: 3 | O24: 0 | AB24: =DEC2HEX(AC24) -> 5 | AC24: =AC23+1 -> 5 | AD24: 15 | AH24: =AH23+1 -> 2141 | AI24: =DEC2HEX(AH24,4) -> 085D | AJ24: 15
H25: 4 | I25: Reading of the results FIFO error | N25: 4 | O25: 0 | X25: Commands | Y25: =Y33 -> Program to be Loaded | AB25: =DEC2HEX(AC25) -> 6 | AC25: =AC24+1 -> 6 | AD25: 0 | AE25: 2 byte BCD of program # PLC is requesting to be loaded when Byte0-Bit3 is set to 1 OR Program to read/write Parameters when Byte0-Bit5 is set to 1 ATEQ screen/program # will be +1 (ATEQ Program #1 = 0, ATEQ Program #11 = 10 dec (000A) Must Validate byte swap may be 0A00 e.g. 0A 00h = program #11 on ATEQ screen | AF25: =DEC2HEX(AG25,4) -> 085B | AG25: =+AG23+1 -> 2139 | AH25: =AH24+1 -> 2142 | AI25: =DEC2HEX(AH25,4) -> 085E | AJ25: 0 | AK25: =HEX2BIN(AL25,8) -> 00001010 | AL25: =RIGHT(DEC2HEX(AP25,4),2) -> 0A | AM25: =CONCATENATE(AL25,AL33) -> 0A00 | AN25: =CONCATENATE(AL33,AL25) -> 000A | AO25: =MOD(HEX2DEC(AM25)+2^15,2^16)-2^15 -> 2560 | AP25: =AR25-1 -> 10 | AQ25: =AO25+1 -> 2561 | AR25: 11 | AS25: Enter ATEQ Program # | AX25: P.1
H26: 5 | I26: Reading of the parameters error | N26: 5 | O26: 0 | AD26: 1 | AJ26: 1
H27: 6 | I27: Writing of the parameters error | N27: 6 | O27: 0 | AD27: 2 | AJ27: 2
H28: 7 | I28: Reset of the results FIFO error | N28: 7 | O28: 0 | AD28: 3 | AJ28: 3
C29: =+B21 -> Error Code | F29: 03 | G29: =HEX2DEC(F29) -> 3 | H29: 0 | I29: Reading of the instrument configuration error | L29: =L21+1 -> 1009 | M29: =DEC2HEX(L29,4) -> 03F1 | N29: 8 | O29: 0 | P29: =BIN2HEX(CONCATENATE(O36,O35,O34,O33,O32,O31,O30,O29)) -> 0 | AD29: 4 | AJ29: 4
H30: 1 | I30: Reading of the general bits error | N30: 9 | O30: 0 | AD30: 5 | AJ30: 5
H31: 2 | I31: Reading of the normal bits error | N31: 10 | O31: 0 | AD31: 6 | AJ31: 6
H32: 3 | I32: Writing of the general bits error | N32: 11 | O32: 0 | AD32: 7 | AJ32: 7
H33: 4 | I33: Writing of the normal bits error | N33: 12 | O33: 0 | Y33: Program to be Loaded | AB33: =DEC2HEX(AC33) -> 7 | AC33: =AC25+1 -> 7 | AD33: 0 | AH33: =AH25+1 -> 2143 | AI33: =DEC2HEX(AH33,4) -> 085F | AJ33: 8 | AK33: =HEX2BIN(AL33,8) -> 00000000 | AL33: =LEFT(DEC2HEX(AP25,4),2) -> 00
H34: 5 | I34: Reading of the program personalisation error | N34: 13 | O34: 0 | AD34: 1 | AJ34: 9
H35: 6 | I35: Writing of the program personalisation error | N35: 14 | O35: 0 | AD35: 2 | AJ35: 10
H36: 7 | I36: Echo writing Last Result Error | N36: 15 | O36: 0 | AD36: 3 | AJ36: 11
A37: Real Time Measurements Real Time Measurements Real Time Measurements Real Time Measurements | B37: Current module in use | C37: =+B37 -> Current module in use | F37: 04 | G37: =HEX2DEC(F37) -> 4 | H37: 0 | I37: Current ATEQ "Head" in use only if multiple heads are connected together via RS485 with an ATEQ C540 central controller | J37: =DEC2HEX(K37,2) -> #NUM! | K37: =+K21+1 -> 1008 | L37: =L29+1 -> 1010 | M37: =DEC2HEX(L37,4) -> 03F2 | N37: 0 | O37: Not Typically Used | AD37: 4 | AJ37: 12
F38: 05 | G38: =HEX2DEC(F38) -> 5 | H38: 15 | L38: =L37+1 -> 1011 | M38: =DEC2HEX(L38,4) -> 03F3 | N38: 15 | AD38: 5 | AJ38: 13 | AX38: pg.235 sample of changing the timers
B39: Current program in use | C39: =+B39 -> Current program in use | F39: 06 | G39: =HEX2DEC(F39) -> 6 | H39: 0 | I39: 2 byte BCD of Current program # selected on ATEQ +1 (ATEQ Program #1 = 0, ATEQ Program #11 = 10 dec (0A00) swapped is 10 dec +1 is program 11 Must Validate byte swap | J39: =DEC2HEX(K39,4) -> 03F1 | K39: =+K37+1 -> 1009 | L39: =L38+1 -> 1012 | M39: =DEC2HEX(L39,4) -> 03F4 | N39: 0 | O39: =HEX2BIN(P39,8) -> 00000000 | P39: 00 | Q39: =CONCATENATE(P39,P47) -> 0000 | R39: =CONCATENATE(P47,P39) -> 0000 | S39: =MOD(HEX2DEC(Q39)+2^15,2^16)-2^15 -> 0 | T39: =MOD(HEX2DEC(R39)+2^15,2^16)-2^15 -> 0 | U39: =S39+1 -> 1 | V39: =T39+1 -> 1 | AD39: 6 | AJ39: 14
H40: 1 | N40: 1 | AD40: 7 | AJ40: 15
H41: 2 | N41: 2 | X41: Commands | Y41: =Y49 -> Special Cycle to be Loaded | AB41: =DEC2HEX(AC41) -> 8 | AC41: =AC33+1 -> 8 | AD41: 0 | AE41: 2 byte BCD code of the "Special Cycle" the PLC is requesting to be loaded when Byte0-Bit2 is set to 1 "Piezo Auto Zero" = 00 07 "Infinite Fill" = 00 11 Code will depend on model of ATEQ F, MF, D etc. Must validate if data is swapped See SPE Cycle tab for other codes | AF41: =DEC2HEX(AG41,4) -> 085C | AG41: =AG25+1 -> 2140 | AH41: =AH33+1 -> 2144 | AI41: =DEC2HEX(AH41,4) -> 0860 | AJ41: 0 | AK41: =HEX2BIN(AL41,8) -> 00000111 | AL41: 07 | AM41: =CONCATENATE(AL41,AL49) -> 0700 | AN41: =CONCATENATE(AL49,AL41) -> 0007 | AO41: =MOD(HEX2DEC(AM41)+2^15,2^16)-2^15 -> 1792 | AP41: =MOD(HEX2DEC(AN41)+2^15,2^16)-2^15 -> 7 | AQ41: Depends on ATEQ Type F, MF, D ect See ATEQ NetworksO manual for "Special Cycle Bit Table" PDF page 63/286
...

Sheet Last Test Results
D2: ATEQ Addresses | I2: PLC INPUT | Z2: ATEQ Input Address | AE2: PLC OUTPUT to ATEQ | AK2: ENTER Binary Value ONLY in GREEN AREAS | AL2: ENTER HEX Value ONLY in GREEN AREAS | AM2: HEX CMD | AN2: HEX CMD Word Swap | AO2: DEC CMD Word | AP2: DEC CMD Word Swap | AQ2: Actual Data Dec | AR2: Actual Data Swap Dec | AS2: Binary | AT2: Cycle Step
D3: Word | F3: Byte | J3: PLC Word INT | P3: Enter Value HEX | Q3: Word HEX | R3: HEX Swap | S3: DEC | T3: Swap DEC | U3: Act Data | V3: Act Data Swap | Z3: Word | AB3: Byte | AF3: PLC Word INT | AH3: Byte
D4: Hex | E4: Dec | F4: Hex | G4: Dec | H4: Bits | I4: Description | J4: Hex | K4: Dec | L4: DEC | M4: HEX | N4: Bits | Z4: Hex | AA4: Dec | AB4: Hex | AC4: Dec | AD4: Bits | AE4: ATEQ Commands | AF4: Hex | AG4: Dec | AH4: Dec | AI4: Hex | AJ4: Bits | AU4: Chapter 21 page 217/286 in NetworksO manual
D5: See LIVE Real Time Control Tab ATEQ Address 00 to 1F for Cycle Control | X5: Commands | Y5: =+X5 -> Commands | AB5: =DEC2HEX(AC5) -> 0 | AC5: 0 | AD5: 0 | AE5: Reset (stop the current cycle) | AF5: =DEC2HEX(AG5,2) -> #NUM! | AG5: ='LIVE Real Time Control'!AG5:AG20 -> 2136 | AH5: =AG5 -> 2136 | AI5: =DEC2HEX(AH5,4) -> 0858 | AJ5: 0 | AK5: 0 | AL5: =BIN2HEX(CONCATENATE(AK12,AK11,AK10,AK9,AK8,AK7,AK6,AK5)) -> 0 | AM5: =CONCATENATE(AL5,AL13) -> 080 | AN5: =CONCATENATE(AL13,AL5) -> 800 | AO5: =MOD(HEX2DEC(AM5)+2^15,2^16)-2^15 -> 128 | AP5: =MOD(HEX2DEC(AN5)+2^15,2^16)-2^15 -> 2048 | AS5: 1 | AT5: 2 | AU5: 2.1.4 PDF Page 223/286 | AV5: Rising edge clears Alarms & Pass/Fail Bits or stops the current cycle
AD6: 1 | AE6: Start (Test or Special cycle) | AJ6: 1 | AK6: 0 | AS6: =AS5*10 -> 10 | AT6: 4 | AU6: 2.1.3 PDF Page 222/286 | AV6: Load Program or Special cycle first then set to 1 rising edge to start
AD7: 2 | AE7: Load Special Cycle code selected at address 8 & 9 | AJ7: 2 | AK7: 0 | AS7: =AS6*10 -> 100 | AU7: 2.1.5 PDF Page 224/286 | AV7: Set Special Cycle code # at 08-09h first then set byte0-Bit2 =1 to load. See chart 1.2 in manual for special cycle options of the unit type used
A8: Last Results Measurements Last Results Measurements Last Results Measurements Last Results Measurements | B8: Program # of Last Results Data | C8: =+B8 -> Program # of Last Results Data | D8: 20 | E8: =HEX2DEC(D8) -> 32 | F8: =DEC2HEX(G8,2) -> 20 | G8: 32 | H8: 0 | I8: 1 Word (2 byte) BCD of Last Results program # ATEQ -1 (ATEQ Program #1 = 0, ATEQ Program #11 = 10 dec (000A) Must Validate byte swap may be 0A00 Data must be moved in to the exchange zone by request set byte1-Bit7=1 to move data | J8: =DEC2HEX(K8,2) -> #NUM! | K8: ='LIVE Real Time Control'!K231+1 -> 1022 | L8: ='LIVE Real Time Control'!L247 -> 1038 | M8: =DEC2HEX(L8,4) -> 040E | N8: 0 | O8: =HEX2BIN(P8,8) -> 00000000 | P8: 00 | Q8: =CONCATENATE(P8,P16) -> 0000 | R8: =CONCATENATE(P16,P8) -> 0000 | S8: =MOD(HEX2DEC(Q8)+2^15,2^16)-2^15 -> 0 | T8: =MOD(HEX2DEC(R8)+2^15,2^16)-2^15 -> 0 | U8: =S8+1 -> 1 | V8: =T8+1 -> 1 | AD8: 3 | AE8: Load Program # selection from 06-07h | AJ8: 3 | AK8: 0 | AS8: =AS7*10 -> 1000 | AT8: 1 | AU8: 2.1.2 PDF Page 221/286 | AV8: Set Program # at 06-07h first then set Byte0-Bit3 =1 to load program # (ATEQ screen is +1, e.g. 06h = 01h (01 = program #2 on ATEQ screen)
H9: 1 | N9: 1 | AD9: 4 | AE9: Read the FIFO cycles results | AJ9: 4 | AK9: 0 | AS9: =AS8*10 -> 10000
H10: 2 | N10: 2 | AD10: 5 | AE10: Read of the parameters | AJ10: 5 | AK10: 0 | AS10: =AS9*10 -> 100000 | AT10: 6 | AU10: 2.2 PDF Page 226/286 | AV10: Moves the test parameters in the exchange zone at address 20h see "Read Parameters" Excel tab
H11: 3 | N11: 3 | AD11: 6 | AE11: Write of the parameters | AJ11: 6 | AK11: 0 | AS11: =AS10*10 -> 1000000
H12: 4 | N12: 4 | AD12: 7 | AE12: Reset of the results in FIFO | AJ12: 7 | AK12: 0 | AS12: =AS11*10 -> 10000000 | AT12: 3 | AU12: 2.5 PDF Page 229/286 | AV12: Clears FIFO to ensure the data moved into the last results is from the last cycle
H13: 5 | N13: 5 | Y13: =+X5 -> Commands | AB13: =DEC2HEX(AC13) -> 1 | AC13: =AC5+1 -> 1 | AD13: 0 | AE13: Read of the instrument configuration | AH13: =AH5+1 -> 2137 | AI13: =DEC2HEX(AH13,4) -> 0859 | AJ13: 8 | AK13: 0 | AL13: =BIN2HEX(CONCATENATE(AK20,AK19,AK18,AK17,AK16,AK15,AK14,AK13)) -> 80 | AS13: 1
H14: 6 | N14: 6 | AD14: 1 | AE14: Read of the general bits. | AJ14: 9 | AK14: 0 | AS14: =AS13*10 -> 10
H15: 7 | N15: 7 | AD15: 2 | AE15: Read of the normal bits. | AJ15: 10 | AK15: 0 | AS15: =AS14*10 -> 100
C16: =+B8 -> Program # of Last Results Data | F16: =DEC2HEX(G16,2) -> 21 | G16: =G8+1 -> 33 | H16: 8 | L16: =L8+1 -> 1039 | M16: =DEC2HEX(L16,4) -> 040F | N16: 8 | O16: =HEX2BIN(P16,8) -> 00000000 | P16: 00 | AD16: 3 | AE16: Write of the general bits. | AJ16: 11 | AK16: 0 | AS16: =AS15*10 -> 1000
H17: 9 | N17: 9 | AD17: 4 | AE17: Write of the normal bits. | AJ17: 12 | AK17: 0 | AS17: =AS16*10 -> 10000
H18: 10 | N18: 10 | AD18: 5 | AE18: Read of the program personalisation | AJ18: 13 | AK18: 0 | AS18: =AS17*10 -> 100000
H19: 11 | N19: 11 | AD19: 6 | AE19: Write of the program personalisation. | AJ19: 14 | AK19: 0 | AS19: =AS18*10 -> 1000000
H20: 12 | N20: 12 | AD20: 7 | AE20: Load Last result pressure and leak data to address 20h | AJ20: 15 | AK20: 1 | AS20: =AS19*10 -> 10000000 | AT20: 5 | AU20: 2.4 PDF Page 228/286 | AV20: Move the Last Results to the exchange zone at address 20h see "Last Results" Excel tab
H21: 13 | N21: 13 | X21: Commands | Y21: =+X21 -> Commands | AB21: =DEC2HEX(AC21) -> 2 | AC21: =AC13+1 -> 2 | AD21: 0 | AE21: NOT USED | AF21: =DEC2HEX(AG21,4) -> 0859 | AG21: =+AG5+1 -> 2137 | AH21: =AH13+1 -> 2138 | AI21: =DEC2HEX(AH21,4) -> 085A | AJ21: 0
H22: 14 | N22: 14 | AB22: =DEC2HEX(AC22) -> 3 | AC22: =AC21+1 -> 3 | AD22: 15 | AE22: NOT USED | AH22: =AH21+1 -> 2139 | AI22: =DEC2HEX(AH22,4) -> 085B | AJ22: 15
H23: 15 | N23: 15 | X23: Commands | Y23: =+X23 -> Commands | AB23: =DEC2HEX(AC23) -> 4 | AC23: =AC22+1 -> 4 | AD23: 0 | AE23: NOT Typically USED Select ATEQ "Head" to send commands Only if multiple heads are connected together via RS485 with an ATEQ C540 central controller Address 04h: Number of the targeted module (C540) selection of the head connected to the C540 central. Address 05h = 0 | AF23: =DEC2HEX(AG23,4) -> 085A | AG23: =+AG21+1 -> 2138 | AH23: =AH22+1 -> 2140 | AI23: =DEC2HEX(AH23,4) -> 085C | AJ23: 0 | AK23: Not Typically Used
B24: Type of test run in Last Results Data | C24: =+B24 -> Type of test run in Last Results Data | D24: 21 | E24: =HEX2DEC(D24) -> 33 | F24: =DEC2HEX(G24,2) -> 22 | G24: =G16+1 -> 34 | H24: 0 | I24: word (2 byte) ATEQ code to identify the type of test run in the Last Results. Test types are identified by, Invalid: 0000, Leak: 0100, Blockage mode: 0200, Desensitized mode: 3000, Operator mode: 0400 and will depend on model of ATEQ F, MF, D etc. Must validate if data is swapped Data must be moved in to the exchange zone by request set byte1-Bit7=1 to move data | J24: =DEC2HEX(K24,2) -> #NUM! | K24: =+K8+1 -> 1023 | L24: =L16+1 -> 1040 | M24: =DEC2HEX(L24,4) -> 0410 | N24: 0 | O24: =HEX2BIN(P24,8) -> 00010000 | P24: 10 | Q24: =CONCATENATE(P24,P32) -> 1000 | R24: =CONCATENATE(P32,P24) -> 0010 | S24: =MOD(HEX2DEC(Q24)+2^15,2^16)-2^15 -> 4096 | T24: =MOD(HEX2DEC(R24)+2^15,2^16)-2^15 -> 16 | U24: Depends on ATEQ Type F, MF, D ect See ATEQ NetworksO manual for "Addresses" | AB24: =DEC2HEX(AC24) -> 5 | AC24: =AC23+1 -> 5 | AD24: 15 | AH24: =AH23+1 -> 2141 | AI24: =DEC2HEX(AH24,4) -> 085D | AJ24: 15
H25: 1 | N25: 1 | X25: Commands | Y25: =Y33 -> Program to be Loaded | AB25: =DEC2HEX(AC25) -> 6 | AC25: =AC24+1 -> 6 | AD25: 0 | AE25: 2 byte BCD of program # PLC is requesting to be loaded when Byte0-Bit3 is set to 1 OR Program to read/write Parameters when Byte0-Bit5 is set to 1 ATEQ screen/program # will be +1 (ATEQ Program #1 = 0, ATEQ Program #11 = 10 dec (000A) Must Validate byte swap may be 0A00 e.g. 0A 00h = program #11 on ATEQ screen | AF25: =DEC2HEX(AG25,4) -> 085B | AG25: =+AG23+1 -> 2139 | AH25: =AH24+1 -> 2142 | AI25: =DEC2HEX(AH25,4) -> 085E | AJ25: 0 | AK25: =HEX2BIN(AL25,8) -> 00000111 | AL25: 07 | AM25: =CONCATENATE(AL25,AL33) -> 0700 | AN25: =CONCATENATE(AL33,AL25) -> 0007 | AO25: =MOD(HEX2DEC(AM25)+2^15,2^16)-2^15 -> 1792 | AP25: =MOD(HEX2DEC(AN25)+2^15,2^16)-2^15 -> 7 | AQ25: =AO25+1 -> 1793 | AR25: =AP25+1 -> 8 | AX25: P.1
H26: 2 | N26: 2 | AD26: 1 | AJ26: 1
H27: 3 | N27: 3 | AD27: 2 | AJ27: 2
H28: 4 | N28: 4 | AD28: 3 | AJ28: 3
H29: 5 | N29: 5 | AD29: 4 | AJ29: 4
H30: 6 | N30: 6 | AD30: 5 | AJ30: 5
H31: 7 | N31: 7 | AD31: 6 | AJ31: 6
C32: =+B24 -> Type of test run in Last Results Data | F32: =DEC2HEX(G32,2) -> 23 | G32: =G24+1 -> 35 | H32: 0 | L32: =L24+1 -> 1041 | M32: =DEC2HEX(L32,4) -> 0411 | N32: 8 | O32: =HEX2BIN(P32,8) -> 00000000 | P32: 00 | AD32: 7 | AJ32: 7
H33: 1 | N33: 9 | Y33: Program to be Loaded | AB33: =DEC2HEX(AC33) -> 7 | AC33: =AC25+1 -> 7 | AD33: 0 | AH33: =AH25+1 -> 2143 | AI33: =DEC2HEX(AH33,4) -> 085F | AJ33: 8 | AK33: =HEX2BIN(AL33,8) -> 00000000 | AL33: 00
H34: 2 | N34: 10 | AD34: 1 | AJ34: 9
H35: 3 | N35: 11 | AD35: 2 | AJ35: 10
H36: 4 | N36: 12 | AD36: 3 | AJ36: 11
H37: 5 | N37: 13 | AD37: 4 | AJ37: 12
H38: 6 | N38: 14 | AD38: 5 | AJ38: 13 | AX38: pg.235 sample of changing the timers
H39: 7 | N39: 15 | AD39: 6 | AJ39: 14
B40: Truncated image of live relays | C40: Truncated image of live relays | D40: 22 | E40: =HEX2DEC(D40) -> 34 | F40: =DEC2HEX(G40,2) -> 24 | G40: =G32+1 -> 36 | H40: 0 | I40: Pass part | J40: =DEC2HEX(K40,2) -> #NUM! | K40: =+K24+1 -> 1024 | L40: =L32+1 -> 1042 | M40: =DEC2HEX(L40,4) -> 0412 | N40: 0 | O40: 0 | P40: =BIN2HEX(CONCATENATE(O47,O46,O45,O44,O43,O42,O41,O40)) -> 8 | Q40: =CONCATENATE(P40,P48) -> 80 | R40: =CONCATENATE(P48,P40) -> 08 | S40: =MOD(HEX2DEC(Q40)+2^15,2^16)-2^15 -> 128 | T40: =MOD(HEX2DEC(R40)+2^15,2^16)-2^15 -> 8 | U40: Use the Live Relay Status Real Time Results Bits for cycle control byte C &D | AD40: 7 | AJ40: 15
H41: 1 | I41: Test fail part | N41: 1 | O41: 0 | X41: Commands | Y41: =Y49 -> Special Cycle to be Loaded | AB41: =DEC2HEX(AC41) -> 8 | AC41: =AC33+1 -> 8 | AD41: 0 | AE41: 2 byte BCD code of the "Special Cycle" the PLC is requesting to be loaded when Byte0-Bit2 is set to 1 "Piezo Auto Zero" = 00 07 "Infinite Fill" = 00 11 Code will depend on model of ATEQ F, MF, D etc. Must validate if data is swapped See SPE Cycle tab for other codes | AF41: =DEC2HEX(AG41,4) -> 085C | AG41: =+AG25+1 -> 2140 | AH41: =AH33+1 -> 2144 | AI41: =DEC2HEX(AH41,4) -> 0860 | AJ41: 0 | AK41: =HEX2BIN(AL41,8) -> 00000111 | AL41: 07 | AM41: =CONCATENATE(AL41,AL49) -> 0700 | AN41: =CONCATENATE(AL49,AL41) -> 0007 | AO41: =MOD(HEX2DEC(AM41)+2^15,2^16)-2^15 -> 1792 | AP41: =MOD(HEX2DEC(AN41)+2^15,2^16)-2^15 -> 7 | AQ41: Depends on ATEQ Type F, MF, D ect See ATEQ NetworksO manual for "Special Cycle Bit Table" PDF page 63/286
...

Sheet Read Parameters
D2: ATEQ Addresses | I2: PLC INPUT | Z2: ATEQ Address | AE2: PLC OUTPUT | AK2: ENTER Binary Value ONLY in GREEN AREAS | AL2: ENTER HEX Value ONLY in GREEN AREAS | AM2: HEX CMD | AN2: HEX CMD Word Swap | AO2: DEC CMD Word | AP2: DEC CMD Word Swap | AQ2: Actual Data Dec | AR2: Actual Data Swap Dec | AS2: Cycle Step | AY2: Select Prog = P.[step]
D3: Word | F3: Byte | J3: PLC Word INT | P3: Enter Value HEX | Q3: Word HEX | R3: HEX Swap | S3: DEC | T3: Swap DEC | U3: Act Data | V3: Act Data Swap | Z3: Word | AB3: Byte | AF3: PLC Word INT | AH3: BYTE
D4: Hex | E4: Dec | F4: Hex | G4: Dec | H4: Bits | I4: Description | J4: Hex | K4: Dec | L4: DEC | M4: HEX | N4: Bits | Z4: Hex | AA4: Dec | AB4: Hex | AC4: Dec | AD4: Bits | AE4: ATEQ Commands | AF4: Hex | AG4: Dec | AH4: DEC | AI4: HEX | AJ4: Bits | AT4: Chapter 21 page 217/286 in NetworksO manual
D5: Go To LIVE Real Time Control Tab ATEQ Address 00 to 1F | X5: Commands | Y5: =+X5 -> Commands | AB5: =DEC2HEX(AC5) -> 0 | AC5: 0 | AD5: 0 | AE5: Reset (stop the current cycle) | AF5: =DEC2HEX(AG5,4) -> 0858 | AG5: ='LIVE Real Time Control'!AG5 -> 2136 | AH5: =AG5 -> 2136 | AI5: =DEC2HEX(AH5,4) -> 0858 | AJ5: 0 | AK5: 0 | AL5: =BIN2HEX(CONCATENATE(AK12,AK11,AK10,AK9,AK8,AK7,AK6,AK5)) -> 20 | AM5: =CONCATENATE(AL5,AL13) -> 200 | AN5: =CONCATENATE(AL13,AL5) -> 020 | AO5: =MOD(HEX2DEC(AM5)+2^15,2^16)-2^15 -> 512 | AP5: =MOD(HEX2DEC(AN5)+2^15,2^16)-2^15 -> 32 | AR5: 1 | AS5: 2 | AT5: 2.1.4 PDF Page 223/286 | AU5: Rising edge clears Alarms & Pass/Fail Bits or stops the current cycle
AD6: 1 | AE6: Start (Test or Special cycle) | AJ6: 1 | AK6: 0 | AR6: =AR5*10 -> 10 | AS6: 4 | AT6: 2.1.3 PDF Page 222/286 | AU6: Load Program or Special cycle first then set to 1 rising edge to start
AD7: 2 | AE7: Load Special Cycle code selected at address 8 & 9 | AJ7: 2 | AK7: 0 | AR7: =AR6*10 -> 100 | AT7: 2.1.5 PDF Page 224/286 | AU7: Set Special Cycle code # at 08-09h first then set byte0-Bit2 =1 to load. See chart 1.2 in manual for special cycle options of the unit type used
A8: Read Parameters & Settings Read Parameters & Settings Read Parameters & Settings Read Parameters & Settings Read Parameters & Settings Read Parameters & Settings Read Parameters & Settings | B8: Parameter I.D. Requested | C8: Parameter I.D. Requested | D8: =DEC2HEX(E8) -> 20 | E8: 32 | F8: =DEC2HEX(G8,2) -> 20 | G8: ='LIVE Real Time Control'!G239+1 -> 32 | H8: 0 | I8: 2 byte BCD of the Parameter I.D. requested in the output word exchange zone e.g. 01 00 is the I.D. for the Fill Time the value is in the next two words | J8: =DEC2HEX(K8,2) -> #NUM! | K8: ='LIVE Real Time Control'!K231+1 -> 1022 | L8: ='LIVE Real Time Control'!L247 -> 1038 | M8: =DEC2HEX(L8,4) -> 040E | N8: 0 | O8: =HEX2BIN(P8,8) -> 00111100 | P8: 3c | Q8: =CONCATENATE(P8,P16) -> 3c00 | R8: =CONCATENATE(P16,P8) -> 003c | S8: =MOD(HEX2DEC(Q8)+2^15,2^16)-2^15 -> 15360 | T8: =MOD(HEX2DEC(R8)+2^15,2^16)-2^15 -> 60 | U8: Depends on Parameter Requested in the output word exchange see ATEQ NetworksO manual PDF page 226 & 247/286 | AD8: 3 | AE8: Load Program # selection from 06-07h | AJ8: 3 | AK8: 0 | AR8: =AR7*10 -> 1000 | AS8: 1 | AT8: 2.1.2 PDF Page 221/286 | AU8: Set Program # at 06-07h first then set Byte0-Bit3 =1 to load program # (ATEQ screen is +1, e.g. 06h = 01h (01 = program #2 on ATEQ screen) | AY8: P.2
H9: 1 | N9: 1 | AD9: 4 | AE9: Read the FIFO cycles results | AJ9: 4 | AK9: 0 | AR9: =AR8*10 -> 10000
H10: 2 | N10: 2 | AD10: 5 | AE10: Read of the parameters | AJ10: 5 | AK10: 1 | AR10: =AR9*10 -> 100000 | AS10: 6 | AT10: 2.2 PDF Page 226/286 | AU10: Moves the test parameters in the exchange zone at address 20h see "Read Parameters" Excel tab
H11: 3 | N11: 3 | AD11: 6 | AE11: Write of the parameters | AJ11: 6 | AK11: 0 | AR11: =AR10*10 -> 1000000
H12: 4 | N12: 4 | AD12: 7 | AE12: Reset of the results in FIFO | AJ12: 7 | AK12: 0 | AR12: =AR11*10 -> 10000000 | AS12: 3 | AT12: 2.5 PDF Page 229/286 | AU12: Clears FIFO to ensure the data moved into the last results is from the last cycle
H13: 5 | N13: 5 | Y13: =+X5 -> Commands | AB13: =DEC2HEX(AC13) -> 1 | AC13: =AC5+1 -> 1 | AD13: 0 | AE13: Read of the instrument configuration | AH13: =AH5+1 -> 2137 | AI13: =DEC2HEX(AH13,4) -> 0859 | AJ13: 8 | AK13: 0 | AL13: =BIN2HEX(CONCATENATE(AK20,AK19,AK18,AK17,AK16,AK15,AK14,AK13)) -> 0 | AR13: 1
H14: 6 | N14: 6 | AD14: 1 | AE14: Read of the general bits. | AJ14: 9 | AK14: 0 | AR14: =AR13*10 -> 10
H15: 7 | N15: 7 | AD15: 2 | AE15: Read of the normal bits. | AJ15: 10 | AK15: 0 | AR15: =AR14*10 -> 100
F16: =DEC2HEX(G16,2) -> 21 | G16: =G8+1 -> 33 | H16: 0 | L16: =L8+1 -> 1039 | M16: =DEC2HEX(L16,4) -> 040F | N16: 8 | O16: =HEX2BIN(P16,8) -> 00000000 | P16: 00 | AD16: 3 | AE16: Write of the general bits. | AJ16: 11 | AK16: 0 | AR16: =AR15*10 -> 1000
H17: 1 | N17: 9 | AD17: 4 | AE17: Write of the normal bits. | AJ17: 12 | AK17: 0 | AR17: =AR16*10 -> 10000
H18: 2 | N18: 10 | AD18: 5 | AE18: Read of the program personalisation | AJ18: 13 | AK18: 0 | AR18: =AR17*10 -> 100000
H19: 3 | N19: 11 | AD19: 6 | AE19: Write of the program personalisation. | AJ19: 14 | AK19: 0 | AR19: =AR18*10 -> 1000000
H20: 4 | N20: 12 | AD20: 7 | AE20: Load Last result pressure and leak data to address 20h | AJ20: 15 | AK20: 0 | AR20: =AR19*10 -> 10000000 | AS20: 5 | AT20: 2.4 PDF Page 228/286 | AU20: Move the Last Results to the exchange zone at address 20h see "Last Results" Excel tab
H21: 5 | N21: 13 | X21: Commands | Y21: =+X21 -> Commands | AB21: =DEC2HEX(AC21) -> 2 | AC21: =AC13+1 -> 2 | AD21: 0 | AE21: NOT USED | AF21: =DEC2HEX(AG21,4) -> 0859 | AG21: =+AG5+1 -> 2137 | AH21: =AH13+1 -> 2138 | AI21: =DEC2HEX(AH21,4) -> 085A | AJ21: 0
H22: 6 | N22: 14 | AB22: =DEC2HEX(AC22) -> 3 | AC22: =AC21+1 -> 3 | AD22: 15 | AE22: NOT USED | AH22: =AH21+1 -> 2139 | AI22: =DEC2HEX(AH22,4) -> 085B | AJ22: 15
H23: 7 | N23: 15 | X23: Commands | Y23: =+X23 -> Commands | AB23: =DEC2HEX(AC23) -> 4 | AC23: =AC22+1 -> 4 | AD23: 0 | AE23: NOT Typically USED Select ATEQ "Head" to send commands Only if multiple heads are connected together via RS485 with an ATEQ C540 central controller Address 04h: Number of the targeted module (C540) selection of the head connected to the C540 central. Address 05h = 0 | AF23: =DEC2HEX(AG23,4) -> 085A | AG23: =+AG21+1 -> 2138 | AH23: =AH22+1 -> 2140 | AI23: =DEC2HEX(AH23,4) -> 085C | AJ23: 0
B24: Parameter Data for I.D. in previous word | C24: Word 1 | D24: =DEC2HEX(E24) -> 21 | E24: =E8+1 -> 33 | F24: =DEC2HEX(G24,2) -> 22 | G24: =G16+1 -> 34 | H24: 0 | I24: Value of Parameter of I.D. requested in the output word exchange zone e.g. I.D. 01 is Fill time D0 07 00 00 swapped multiplied by *0.001 = 2.00 seconds | J24: =DEC2HEX(K24,2) -> #NUM! | K24: =+K8+1 -> 1023 | L24: =L16+1 -> 1040 | M24: =DEC2HEX(L24,4) -> 0410 | N24: 0 | O24: =HEX2BIN(P24,8) -> 01110000 | P24: 70 | Q24: =CONCATENATE(P24,P32,P40,P48) -> 70170000 | R24: =CONCATENATE(P48,P40,P32,P24) -> 00001770 | S24: =MOD(HEX2DEC(Q24)+2^31,2^32)-2^31 -> 1880555520 | T24: =(MOD(HEX2DEC(R24)+2^31,2^32)-2^31) -> 6000 | U24: =S24*0.001 -> 1880555.5 | V24: =T24*0.001 -> 6 | AB24: =DEC2HEX(AC24) -> 5 | AC24: =AC23+1 -> 5 | AD24: 15 | AH24: =AH23+1 -> 2141 | AI24: =DEC2HEX(AH24,4) -> 085D | AJ24: 15
H25: 1 | N25: 1 | X25: Commands | Y25: =Y33 -> Program to be Loaded | AB25: =DEC2HEX(AC25) -> 6 | AC25: =AC24+1 -> 6 | AD25: 0 | AE25: 2 byte BCD of program # PLC is requesting to be loaded when Address 0h-Bit3 is set to 1 OR Program Number to Read Pramaters from ATEQ screen will be -1 (ATEQ Program #1 = 0, ATEQ Program #11 = 10 dec (000A) Must Validate byte swap may be 0A00(ATEQ screen is +1, e.g. 06h = 01h (01 = program #2 on ATEQ screen)Address 06h: Number of the program to be selected. Address 07h =0 | AF25: =DEC2HEX(AG25,4) -> 085B | AG25: =+AG23+1 -> 2139 | AH25: =AH24+1 -> 2142 | AI25: =DEC2HEX(AH25,4) -> 085E | AJ25: 0 | AK25: =HEX2BIN(AL25,8) -> 00001010 | AL25: =RIGHT(DEC2HEX(AP25,4),2) -> 0A | AM25: =CONCATENATE(AL25,AL33) -> 0A00 | AN25: =CONCATENATE(AL33,AL25) -> 000A | AO25: =MOD(HEX2DEC(AM25)+2^15,2^16)-2^15 -> 2560 | AP25: =AR25-1 -> 10 | AQ25: =AO25+1 -> 2561 | AR25: 11 | AS25: Enter ATEQ Program #
H26: 2 | N26: 2 | AD26: 1 | AJ26: 1
H27: 3 | N27: 3 | AD27: 2 | AJ27: 2
H28: 4 | N28: 4 | AD28: 3 | AJ28: 3
H29: 5 | N29: 5 | AD29: 4 | AJ29: 4
H30: 6 | N30: 6 | AD30: 5 | AJ30: 5
H31: 7 | N31: 7 | AD31: 6 | AJ31: 6
F32: =DEC2HEX(G32,2) -> 23 | G32: =G24+1 -> 35 | H32: 0 | L32: =L24+1 -> 1041 | M32: =DEC2HEX(L32,4) -> 0411 | N32: 8 | O32: =HEX2BIN(P32,8) -> 00010111 | P32: 17 | AD32: 7 | AJ32: 7
H33: 1 | N33: 9 | Y33: Program to be Loaded | AB33: =DEC2HEX(AC33) -> 7 | AC33: =AC25+1 -> 7 | AD33: 0 | AH33: =AH25+1 -> 2143 | AI33: =DEC2HEX(AH33,4) -> 085F | AJ33: 8 | AK33: =HEX2BIN(AL33,8) -> 00000000 | AL33: =LEFT(DEC2HEX(AP25,4),2) -> 00
H34: 2 | N34: 10 | AD34: 1 | AJ34: 9
H35: 3 | N35: 11 | AD35: 2 | AJ35: 10
H36: 4 | N36: 12 | AD36: 3 | AJ36: 11
H37: 5 | N37: 13 | AD37: 4 | AJ37: 12
H38: 6 | N38: 14 | AD38: 5 | AJ38: 13
H39: 7 | N39: 15 | AD39: 6 | AJ39: 14
C40: Word 2 | D40: =DEC2HEX(E40) -> 22 | E40: =E24+1 -> 34 | F40: =DEC2HEX(G40,2) -> 24 | G40: =G32+1 -> 36 | H40: 0 | J40: =DEC2HEX(K40,2) -> #NUM! | K40: =+K24+1 -> 1024 | L40: =L32+1 -> 1042 | M40: =DEC2HEX(L40,4) -> 0412 | N40: 0 | O40: =HEX2BIN(P40,8) -> 00000000 | P40: 00 | AD40: 7 | AJ40: 15
H41: 1 | N41: 1 | X41: Commands | Y41: =Y42 -> 0 | AB41: =DEC2HEX(AC41) -> 8 | AC41: =AC33+1 -> 8 | AD41: 0-7 | AE41: 2 byte BCD code of the "Special Cycle" the PLC is requesting to be loaded when Address 0h-Bit2 is set to 1 "Piezo Auto Zero" = 00 07 "Infinite Fill" = 00 11 Code will depend on model of ATEQ F, MF, D etc. Must validate if data is swapped See SPE Cycle tab for other codes | AF41: =DEC2HEX(AG41,4) -> 085C | AG41: =+AG25+1 -> 2140 | AH41: =AH33+1 -> 2144 | AI41: =DEC2HEX(AH41,4) -> 0860 | AJ41: 0-7
...

Sheet Write Parameters 
D2: ATEQ Addresses | I2: PLC INPUT | Z2: ATEQ Address | AE2: PLC OUTPUT | AK2: ENTER Binary Value ONLY in GREEN AREAS | AL2: ENTER HEX Value ONLY in GREEN AREAS | AM2: HEX CMD | AN2: HEX CMD Word Swap | AO2: DEC CMD Word | AP2: DEC CMD Word Swap | AQ2: Actual Data Dec | AR2: Actual Data Dec swaped
D3: Word | F3: Byte | J3: PLC Word INT | P3: Enter Value HEX | Q3: Word HEX | R3: HEX Swap | S3: DEC | T3: Swap DEC | U3: Act Data | V3: Act Data Swap | Z3: Word | AB3: Byte | AF3: PLC Word INT | AH3: BYTE
D4: Hex | E4: Dec | F4: Hex | G4: Dec | H4: Bits | I4: Description | J4: Hex | K4: Dec | L4: DEC | M4: HEX | N4: Bits | Z4: Hex | AA4: Dec | AB4: Hex | AC4: Dec | AD4: Bits | AE4: ATEQ Commands | AF4: Hex | AG4: Dec | AH4: DEC | AI4: HEX | AJ4: Bits
A5: Real Time Measurements Real Time Measurements Real Time Measurements Real Time Measurements | B5: Echo Signals | C5: Echo Signals | F5: 00 | G5: =HEX2DEC(F5) -> 0 | H5: 0 | I5: Echo reset | J5: =DEC2HEX(K5,4) -> 03EE | K5: ='LIVE Real Time Control'!K5 -> 1006 | L5: =K5 -> 1006 | M5: =DEC2HEX(L5,4) -> 03EE | N5: 0 | O5: Read Parameters and Settings at A79 | X5: Commands | Y5: =+X5 -> Commands | AB5: =DEC2HEX(AC5) -> 0 | AC5: 0 | AD5: 0 | AE5: Reset (stop the current cycle) | AF5: =DEC2HEX(AG5,4) -> 0858 | AG5: ='LIVE Real Time Control'!AG5 -> 2136 | AH5: =AG5 -> 2136 | AI5: =DEC2HEX(AH5,4) -> 0858 | AJ5: 0 | AK5: 0 | AL5: =BIN2HEX(CONCATENATE(AK12,AK11,AK10,AK9,AK8,AK7,AK6,AK5)) -> 40 | AM5: =CONCATENATE(AL5,AL13) -> 400 | AN5: =CONCATENATE(AL13,AL5) -> 040 | AO5: =MOD(HEX2DEC(AM5)+2^15,2^16)-2^15 -> 1024 | AP5: =MOD(HEX2DEC(AN5)+2^15,2^16)-2^15 -> 64
H6: 1 | I6: Echo start | N6: 1 | AD6: 1 | AE6: Start (Test or Special cycle) | AJ6: 1 | AK6: 0
H7: 2 | I7: Echo special cycle | N7: 2 | AD7: 2 | AE7: Load Special Cycle code selected at address 8 & 9 | AJ7: 2 | AK7: 0
H8: 3 | I8: Echo program selection | N8: 3 | AD8: 3 | AE8: Load Program # selection from 06-07h | AJ8: 3 | AK8: 0
H9: 4 | I9: Echo reading of the results FIFO | N9: 4 | AD9: 4 | AE9: Read the FIFO cycles results | AJ9: 4 | AK9: 0
H10: 5 | I10: Echo reading of the parameters | N10: 5 | AD10: 5 | AE10: Read of the parameters | AJ10: 5 | AK10: 0
H11: 6 | I11: Echo writing of the parameters | N11: 6 | AD11: 6 | AE11: Write of the parameters | AJ11: 6 | AK11: 1
H12: 7 | I12: Echo reset of the results FIFO | N12: 7 | AD12: 7 | AE12: Reset of the results in FIFO | AJ12: 7 | AK12: 0
C13: Echo Signals | F13: 01 | G13: =HEX2DEC(F13) -> 1 | H13: 0 | I13: Echo reading of the instrument configuration | L13: =L5+1 -> 1007 | M13: =DEC2HEX(L13,4) -> 03EF | N13: 8 | Y13: =+X5 -> Commands | AB13: =DEC2HEX(AC13) -> 1 | AC13: =AC5+1 -> 1 | AD13: 0 | AE13: Read of the instrument configuration | AH13: =AH5+1 -> 2137 | AI13: =DEC2HEX(AH13,4) -> 0859 | AJ13: 8 | AK13: 0 | AL13: =BIN2HEX(CONCATENATE(AK20,AK19,AK18,AK17,AK16,AK15,AK14,AK13)) -> 0
H14: 1 | I14: Echo reading of the general bits | N14: 9 | AD14: 1 | AE14: Read of the general bits. | AJ14: 9 | AK14: 0
H15: 2 | I15: Echo reading of the normal bits | N15: 10 | AD15: 2 | AE15: Read of the normal bits. | AJ15: 10 | AK15: 0
H16: 3 | I16: Echo writing of the general bits | N16: 11 | AD16: 3 | AE16: Write of the general bits. | AJ16: 11 | AK16: 0
H17: 4 | I17: Echo writing of the normal bits | N17: 12 | AD17: 4 | AE17: Write of the normal bits. | AJ17: 12 | AK17: 0
H18: 5 | I18: Echo reading of the program personalisation | N18: 13 | AD18: 5 | AE18: Read of the program personalisation | AJ18: 13 | AK18: 0
H19: 6 | I19: Echo writing of the program personalisation | N19: 14 | AD19: 6 | AE19: Write of the program personalisation. | AJ19: 14 | AK19: 0
H20: 7 | I20: Echo writing Last Result | N20: 15 | AD20: 7 | AE20: Load Last result pressure and leak data to address 20h | AJ20: 15 | AK20: 0
B21: Error Code | C21: =+B21 -> Error Code | F21: 02 | G21: =HEX2DEC(F21) -> 2 | H21: 0 | I21: Reset error | J21: =DEC2HEX(K21,4) -> 03EF | K21: =+K5+1 -> 1007 | L21: =L13+1 -> 1008 | M21: =DEC2HEX(L21,4) -> 03F0 | N21: 0 | X21: Commands | Y21: =+X21 -> Commands | AB21: =DEC2HEX(AC21) -> 2 | AC21: =AC13+1 -> 2 | AD21: 0 | AE21: NOT USED | AF21: =DEC2HEX(AG21,4) -> 0859 | AG21: =+AG5+1 -> 2137 | AH21: =AH13+1 -> 2138 | AI21: =DEC2HEX(AH21,4) -> 085A | AJ21: 0
H22: 1 | I22: Start error | N22: 1 | AB22: =DEC2HEX(AC22) -> 3 | AC22: =AC21+1 -> 3 | AD22: 15 | AE22: NOT USED | AH22: =AH21+1 -> 2139 | AI22: =DEC2HEX(AH22,4) -> 085B | AJ22: 15
H23: 2 | I23: Special cycle error | N23: 2 | X23: Commands | Y23: =+X23 -> Commands | AB23: =DEC2HEX(AC23) -> 4 | AC23: =AC22+1 -> 4 | AD23: 0 | AE23: NOT Typically USED Select ATEQ "Head" to send commands Only if multiple heads are connected together via RS485 with an ATEQ C540 central controller Address 04h: Number of the targeted module (C540) selection of the head connected to the C540 central. Address 05h = 0 | AF23: =DEC2HEX(AG23,4) -> 085A | AG23: =+AG21+1 -> 2138 | AH23: =AH22+1 -> 2140 | AI23: =DEC2HEX(AH23,4) -> 085C | AJ23: 0
H24: 3 | I24: Program selection error | N24: 3 | AB24: =DEC2HEX(AC24) -> 5 | AC24: =AC23+1 -> 5 | AD24: 15 | AH24: =AH23+1 -> 2141 | AI24: =DEC2HEX(AH24,4) -> 085D | AJ24: 15
H25: 4 | I25: Reading of the results FIFO error | N25: 4 | X25: Commands | Y25: =Y33 -> Program to be Loaded | AB25: =DEC2HEX(AC25) -> 6 | AC25: =AC24+1 -> 6 | AD25: 0 | AE25: 2 byte BCD of program # PLC is requesting to be loaded when Address 0h-Bit3 is set to 1 OR Program Number to Read/Write Pramaters from ATEQ screen will be -1 (ATEQ Program #1 = 0, ATEQ Program #11 = 10 dec (000A) Must Validate byte swap may be 0A00(ATEQ screen is +1, e.g. 06h = 01h (01 = program #2 on ATEQ screen)Address 06h: Number of the program to be selected. Address 07h =0 | AF25: =DEC2HEX(AG25,4) -> 085B | AG25: =+AG23+1 -> 2139 | AH25: =AH24+1 -> 2142 | AI25: =DEC2HEX(AH25,4) -> 085E | AJ25: 0 | AK25: =HEX2BIN(AL25,8) -> 00001010 | AL25: =RIGHT(DEC2HEX(AP25,4),2) -> 0A | AM25: =CONCATENATE(AL25,AL33) -> 0A00 | AN25: =CONCATENATE(AL33,AL25) -> 000A | AO25: =MOD(HEX2DEC(AM25)+2^15,2^16)-2^15 -> 2560 | AP25: =AR25-1 -> 10 | AQ25: =AO25+1 -> 2561 | AR25: 11 | AS25: Enter ATEQ Program #
H26: 5 | I26: Reading of the parameters error | N26: 5 | AD26: 1 | AJ26: 1
H27: 6 | I27: Writing of the parameters error | N27: 6 | AD27: 2 | AJ27: 2
H28: 7 | I28: Reset of the results FIFO error | N28: 7 | AD28: 3 | AJ28: 3
C29: =+B21 -> Error Code | F29: 03 | G29: =HEX2DEC(F29) -> 3 | H29: 0 | I29: Reading of the instrument configuration error | L29: =L21+1 -> 1009 | M29: =DEC2HEX(L29,4) -> 03F1 | N29: 8 | AD29: 4 | AJ29: 4
H30: 1 | I30: Reading of the general bits error | N30: 9 | AD30: 5 | AJ30: 5
H31: 2 | I31: Reading of the normal bits error | N31: 10 | AD31: 6 | AJ31: 6
H32: 3 | I32: Writing of the general bits error | N32: 11 | AD32: 7 | AJ32: 7
H33: 4 | I33: Writing of the normal bits error | N33: 12 | Y33: Program to be Loaded | AB33: =DEC2HEX(AC33) -> 7 | AC33: =AC25+1 -> 7 | AD33: 0 | AH33: =AH25+1 -> 2143 | AI33: =DEC2HEX(AH33,4) -> 085F | AJ33: 8 | AK33: =HEX2BIN(AL33,8) -> 00000000 | AL33: =LEFT(DEC2HEX(AP25,4),2) -> 00
H34: 5 | I34: Reading of the program personalisation error | N34: 13 | AD34: 1 | AJ34: 9
H35: 6 | I35: Writing of the program personalisation error | N35: 14 | AD35: 2 | AJ35: 10
H36: 7 | I36: Echo writing Last Result Error | N36: 15 | AD36: 3 | AJ36: 11
F37: 04 | G37: =HEX2DEC(F37) -> 4 | H37: 0 | I37: Current ATEQ "Head" in use only if multiple heads are connected together via RS485 with an ATEQ C540 central controller | J37: =DEC2HEX(K37,4) -> 03F0 | K37: =+K21+1 -> 1008 | L37: =L29+1 -> 1010 | M37: =DEC2HEX(L37,4) -> 03F2 | N37: 0-7 | O37: LIVE Real Time Control | AD37: 4 | AJ37: 12
F38: 05 | G38: =HEX2DEC(F38) -> 5 | H38: 15 | L38: =L37+1 -> 1011 | M38: =DEC2HEX(L38,4) -> 03F3 | N38: 8-15 | AD38: 5 | AJ38: 13
F39: 06 | G39: =HEX2DEC(F39) -> 6 | H39: 0 | I39: 2 byte BCD of Current program # selected on ATEQ -1 (ATEQ Program #1 = 0, ATEQ Program #11 = 10 dec (000A) Must Validate byte swap may be 0A00 | J39: =DEC2HEX(K39,4) -> 03F1 | K39: =+K37+1 -> 1009 | L39: =L38+1 -> 1012 | M39: =DEC2HEX(L39,4) -> 03F4 | N39: 0-7 | AD39: 6 | AJ39: 14
F40: 07 | G40: =HEX2DEC(F40) -> 7 | H40: 0 | L40: =L39+1 -> 1013 | M40: =DEC2HEX(L40,4) -> 03F5 | N40: 8-15 | AD40: 7 | AJ40: 15
F41: 08 | G41: =HEX2DEC(F41) -> 8 | H41: 0 | I41: 2 byte BCD of Number of Results in FIFO Must Validate byte swap 0001 may be 0100 | J41: =DEC2HEX(K41,4) -> 03F2 | K41: =+K39+1 -> 1010 | L41: =L40+1 -> 1014 | M41: =DEC2HEX(L41,4) -> 03F6 | N41: 0-7 | X41: Commands | Y41: =Y42 -> 0 | AB41: =DEC2HEX(AC41) -> 8 | AC41: =AC33+1 -> 8 | AD41: 0-7 | AE41: 2 byte BCD code of the "Special Cycle" the PLC is requesting to be loaded when Address 0h-Bit2 is set to 1 "Piezo Auto Zero" = 00 07 "Infinite Fill" = 00 11 Code will depend on model of ATEQ F, MF, D etc. Must validate if data is swapped See SPE Cycle tab for other codes | AF41: =DEC2HEX(AG41,4) -> 085C | AG41: =+AG25+1 -> 2140 | AH41: =AH33+1 -> 2144 | AI41: =DEC2HEX(AH41,4) -> 0860 | AJ41: 0-7
...

Sheet PUN
D2: ATEQ Addresses | I2: PLC INPUT | X2: ATEQ Address | AC2: PLC OUTPUT | AI2: ENTER Binary or Text ONLY in GREEN AREAS | AJ2: ENTER HEX Value ONLY in GREEN AREAS | AK2: HEX CMD | AL2: HEX CMD Word Swap | AM2: DEC CMD Word | AN2: DEC CMD Word Swap | AO2: Actual Data Dec | AP2: Actual Data Dec swaped | AQ2: Cycle Step | AW2: Select Prog = P.[step]
D3: Word | F3: Byte | J3: PLC Word INT | N3: Enter Value HEX | O3: Word HEX | P3: HEX Swap | Q3: DEC | R3: Swap DEC | S3: Act Data | T3: Act Data Swap | X3: Word | Z3: Byte | AD3: PLC Word INT | AF3: BYTE
D4: Hex | E4: Dec | F4: Hex | G4: Dec | H4: Bits | I4: Description | J4: Hex | K4: Dec | L4: Bits | X4: Hex | Y4: Dec | Z4: Hex | AA4: Dec | AB4: Bits | AC4: ATEQ Commands | AD4: Hex | AE4: Dec | AF4: DEC | AG4: HEX | AH4: Bits | AR4: Chapter 21 page 217/286 in NetworksO manual
A5: Real Time Measurements Real Time Measurements Real Time Measurements Real Time Measurements | B5: Echo Signals | C5: Echo Signals | F5: 00 | G5: =HEX2DEC(F5) -> 0 | H5: 0 | I5: Echo reset | J5: =DEC2HEX(K5,2) -> #NUM! | K5: ='LIVE Real Time Control'!K5 -> 1006 | L5: 0 | M5: Read Parameters and Settings at A79 | V5: Commands | W5: =+V5 -> Commands | Z5: =DEC2HEX(AA5) -> 0 | AA5: 0 | AB5: 0 | AC5: Reset (stop the current cycle) | AD5: =DEC2HEX(AE5,4) -> 0858 | AE5: ='LIVE Real Time Control'!AG5 -> 2136 | AF5: =AE5 -> 2136 | AG5: =DEC2HEX(AF5,4) -> 0858 | AH5: 0 | AI5: 0 | AJ5: =BIN2HEX(CONCATENATE(AI12,AI11,AI10,AI9,AI8,AI7,AI6,AI5)) -> 0 | AK5: =CONCATENATE(AJ5,AJ13) -> 040 | AL5: =CONCATENATE(AJ13,AJ5) -> 400 | AM5: =MOD(HEX2DEC(AK5)+2^15,2^16)-2^15 -> 64 | AN5: =MOD(HEX2DEC(AL5)+2^15,2^16)-2^15 -> 1024 | AQ5: 2 | AR5: 2.1.4 PDF Page 223/286 | AS5: Rising edge clears Alarms & Pass/Fail Bits or stops the current cycle
H6: 1 | I6: Echo start | L6: 1 | AB6: 1 | AC6: Start (Test or Special cycle) | AH6: 1 | AI6: 0 | AQ6: 4 | AR6: 2.1.3 PDF Page 222/286 | AS6: Load Program or Special cycle first then set to 1 rising edge to start
H7: 2 | I7: Echo special cycle | L7: 2 | AB7: 2 | AC7: Load Special Cycle code selected at address 8 & 9 | AH7: 2 | AI7: 0 | AR7: 2.1.5 PDF Page 224/286 | AS7: Set Special Cycle code # at 08-09h first then set byte0-Bit2 =1 to load. See chart 1.2 in manual for special cycle options of the unit type used
H8: 3 | I8: Echo program selection | L8: 3 | AB8: 3 | AC8: Load Program # selection from 06-07h | AH8: 3 | AI8: 0 | AQ8: 1 | AR8: 2.1.2 PDF Page 221/286 | AS8: Set Program # at 06-07h first then set Byte0-Bit3 =1 to load program # (ATEQ screen is +1, e.g. 06h = 01h (01 = program #2 on ATEQ screen) | AW8: P.2
H9: 4 | I9: Echo reading of the results FIFO | L9: 4 | AB9: 4 | AC9: Read the FIFO cycles results | AH9: 4 | AI9: 0
H10: 5 | I10: Echo reading of the parameters | L10: 5 | AB10: 5 | AC10: Read of the parameters | AH10: 5 | AI10: 0 | AQ10: 6 | AR10: 2.2 PDF Page 226/286 | AS10: Moves the test parameters in the exchange zone at address 20h see "Read Parameters" Excel tab
H11: 6 | I11: Echo writing of the parameters | L11: 6 | AB11: 6 | AC11: Write of the parameters | AH11: 6 | AI11: 0
H12: 7 | I12: Echo reset of the results FIFO | L12: 7 | AB12: 7 | AC12: Reset of the results in FIFO | AH12: 7 | AI12: 0 | AQ12: 3 | AR12: 2.5 PDF Page 229/286 | AS12: Clears FIFO to ensure the data moved into the last results is from the last cycle
C13: Echo Signals | F13: 01 | G13: =HEX2DEC(F13) -> 1 | H13: 0 | I13: Echo reading of the instrument configuration | L13: 8 | W13: =+V5 -> Commands | Z13: =DEC2HEX(AA13) -> 1 | AA13: =AA5+1 -> 1 | AB13: 0 | AC13: Read of the instrument configuration | AF13: =AF5+1 -> 2137 | AG13: =DEC2HEX(AF13,4) -> 0859 | AH13: 8 | AI13: 0 | AJ13: =BIN2HEX(CONCATENATE(AI20,AI19,AI18,AI17,AI16,AI15,AI14,AI13)) -> 40
H14: 1 | I14: Echo reading of the general bits | L14: 9 | AB14: 1 | AC14: Read of the general bits. | AH14: 9 | AI14: 0
H15: 2 | I15: Echo reading of the normal bits | L15: 10 | AB15: 2 | AC15: Read of the normal bits. | AH15: 10 | AI15: 0
H16: 3 | I16: Echo writing of the general bits | L16: 11 | AB16: 3 | AC16: Write of the general bits. | AH16: 11 | AI16: 0
H17: 4 | I17: Echo writing of the normal bits | L17: 12 | AB17: 4 | AC17: Write of the normal bits. | AH17: 12 | AI17: 0
H18: 5 | I18: Echo reading of the program personalisation | L18: 13 | AB18: 5 | AC18: Read of the program personalisation | AH18: 13 | AI18: 0
H19: 6 | I19: Echo writing of the program personalisation | L19: 14 | AB19: 6 | AC19: Write of the program personalisation. | AH19: 14 | AI19: 1
H20: 7 | I20: Echo writing Last Result | L20: 15 | AB20: 7 | AC20: Load Last result pressure and leak data to address 20h | AH20: 15 | AI20: 0 | AR20: 2.4 PDF Page 228/286 | AS20: Move the Last Results to the exchange zone at address 20h see "Last Results" Excel tab
B21: Error Code | C21: =+B21 -> Error Code | F21: 02 | G21: =HEX2DEC(F21) -> 2 | H21: 0 | I21: Reset error | J21: =DEC2HEX(K21,2) -> #NUM! | K21: =+K5+1 -> 1007 | L21: 0 | V21: Commands | W21: =+V21 -> Commands | Z21: =DEC2HEX(AA21) -> 2 | AA21: =AA13+1 -> 2 | AB21: 0 | AC21: NOT USED | AD21: =DEC2HEX(AE21,4) -> 0859 | AE21: =+AE5+1 -> 2137 | AF21: =AF13+1 -> 2138 | AG21: =DEC2HEX(AF21,4) -> 085A | AH21: 0
H22: 1 | I22: Start error | L22: 1 | Z22: =DEC2HEX(AA22) -> 3 | AA22: =AA21+1 -> 3 | AB22: 15 | AC22: NOT USED | AF22: =AF21+1 -> 2139 | AG22: =DEC2HEX(AF22,4) -> 085B | AH22: 15
H23: 2 | I23: Special cycle error | L23: 2 | V23: Commands | W23: =+V23 -> Commands | Z23: =DEC2HEX(AA23) -> 4 | AA23: =AA22+1 -> 4 | AB23: 0 | AC23: NOT Typically USED Select ATEQ "Head" to send commands Only if multiple heads are connected together via RS485 with an ATEQ C540 central controller Address 04h: Number of the targeted module (C540) selection of the head connected to the C540 central. Address 05h = 0 | AD23: =DEC2HEX(AE23,4) -> 085A | AE23: =+AE21+1 -> 2138 | AF23: =AF22+1 -> 2140 | AG23: =DEC2HEX(AF23,4) -> 085C | AH23: 0
H24: 3 | I24: Program selection error | L24: 3 | Z24: =DEC2HEX(AA24) -> 5 | AA24: =AA23+1 -> 5 | AB24: 15 | AF24: =AF23+1 -> 2141 | AG24: =DEC2HEX(AF24,4) -> 085D | AH24: 15
H25: 4 | I25: Reading of the results FIFO error | L25: 4 | V25: Commands | W25: =W33 -> Program to be Loaded | Z25: =DEC2HEX(AA25) -> 6 | AA25: =AA24+1 -> 6 | AB25: 0 | AC25: 2 byte BCD of program # PLC is requesting to be loaded when Address 0h-Bit3 is set to 1 OR Program Number to Read Pramaters from ATEQ screen will be -1 (ATEQ Program #1 = 0, ATEQ Program #11 = 10 dec (000A) Must Validate byte swap may be 0A00(ATEQ screen is +1, e.g. 06h = 01h (01 = program #2 on ATEQ screen)Address 06h: Number of the program to be selected. Address 07h =0 | AD25: =DEC2HEX(AE25,4) -> 085B | AE25: =+AE23+1 -> 2139 | AF25: =AF24+1 -> 2142 | AG25: =DEC2HEX(AF25,4) -> 085E | AH25: 0 | AI25: =HEX2BIN(AJ25,8) -> 00001010 | AJ25: =RIGHT(DEC2HEX(AN25,4),2) -> 0A | AK25: =CONCATENATE(AJ25,AJ33) -> 0A00 | AL25: =CONCATENATE(AJ33,AJ25) -> 000A | AM25: =MOD(HEX2DEC(AK25)+2^15,2^16)-2^15 -> 2560 | AN25: =AP25-1 -> 10 | AO25: =AM25+1 -> 2561 | AP25: 11 | AQ25: Enter ATEQ Program #
H26: 5 | I26: Reading of the parameters error | L26: 5 | AB26: 1 | AH26: 1
H27: 6 | I27: Writing of the parameters error | L27: 6 | AB27: 2 | AH27: 2
H28: 7 | I28: Reset of the results FIFO error | L28: 7 | AB28: 3 | AH28: 3
C29: =+B21 -> Error Code | F29: 03 | G29: =HEX2DEC(F29) -> 3 | H29: 0 | I29: Reading of the instrument configuration error | L29: 8 | AB29: 4 | AH29: 4
H30: 1 | I30: Reading of the general bits error | L30: 9 | AB30: 5 | AH30: 5
H31: 2 | I31: Reading of the normal bits error | L31: 10 | AB31: 6 | AH31: 6
H32: 3 | I32: Writing of the general bits error | L32: 11 | AB32: 7 | AH32: 7
H33: 4 | I33: Writing of the normal bits error | L33: 12 | W33: Program to be Loaded | Z33: =DEC2HEX(AA33) -> 7 | AA33: =AA25+1 -> 7 | AB33: 0 | AF33: =AF25+1 -> 2143 | AG33: =DEC2HEX(AF33,4) -> 085F | AH33: 8 | AI33: =HEX2BIN(AJ33,8) -> 00000000 | AJ33: =LEFT(DEC2HEX(AN25,4),2) -> 00
H34: 5 | I34: Reading of the program personalisation error | L34: 13 | AB34: 1 | AH34: 9
H35: 6 | I35: Writing of the program personalisation error | L35: 14 | AB35: 2 | AH35: 10
H36: 7 | I36: Echo writing Last Result Error | L36: 15 | AB36: 3 | AH36: 11
F37: 04 | G37: =HEX2DEC(F37) -> 4 | H37: 0 | I37: Current ATEQ "Head" in use only if multiple heads are connected together via RS485 with an ATEQ C540 central controller | J37: =DEC2HEX(K37,2) -> #NUM! | K37: =+K21+1 -> 1008 | L37: 0-7 | M37: LIVE Real Time Control | AB37: 4 | AH37: 12
F38: 05 | G38: =HEX2DEC(F38) -> 5 | H38: 15 | L38: 8-15 | AB38: 5 | AH38: 13
F39: 06 | G39: =HEX2DEC(F39) -> 6 | H39: 0 | I39: 2 byte BCD of Current program # selected on ATEQ -1 (ATEQ Program #1 = 0, ATEQ Program #11 = 10 dec (000A) Must Validate byte swap may be 0A00 | J39: =DEC2HEX(K39,2) -> #NUM! | K39: =+K37+1 -> 1009 | L39: 0-7 | AB39: 6 | AH39: 14
F40: 07 | G40: =HEX2DEC(F40) -> 7 | H40: 0 | L40: 8-15 | AB40: 7 | AH40: 15
F41: 08 | G41: =HEX2DEC(F41) -> 8 | H41: 0 | I41: 2 byte BCD of Number of Results in FIFO Must Validate byte swap 0001 may be 0100 | J41: =DEC2HEX(K41,2) -> #NUM! | K41: =+K39+1 -> 1010 | L41: 0-7 | V41: Commands | W41: =W42 -> 0 | Z41: =DEC2HEX(AA41) -> 8 | AA41: =AA33+1 -> 8 | AB41: 0-7 | AC41: 2 byte BCD code of the "Special Cycle" the PLC is requesting to be loaded when Address 0h-Bit2 is set to 1 "Piezo Auto Zero" = 00 07 "Infinite Fill" = 00 11 Code will depend on model of ATEQ F, MF, D etc. Must validate if data is swapped See SPE Cycle tab for other codes | AD41: =DEC2HEX(AE41,4) -> 085C | AE41: =+AE25+1 -> 2140 | AF41: =AF33+1 -> 2144 | AG41: =DEC2HEX(AF41,4) -> 0860 | AH41: 0-7
...

Sheet ASCII to Hex
A1: 6D792062726F776E20646F67 | C1: HEX | D1: DEC | M1: Character | N1: 1 | O1: 2 | P1: 3 | Q1: 4 | R1: 5 | S1: 6 | T1: 7 | U1: 8 | V1: 9 | W1: 10 | X1: 11 | Y1: 12 | Z1: 13 | AA1: 14 | AB1: 15 | AC1: 16 | AD1: 17 | AE1: 18 | AF1: 19 | AG1: 20
A2: Start of Text | B2: STX | C2: 2 | D2: =HEX2DEC(C2) -> 2 | K2: =CONCATENATE((CHAR(HEX2DEC(MID(A1,1,2)))),(CHAR(HE X2DEC(MID(A1,3,2)))),(CHAR(HEX2DEC(MID(A1,5,2)))), (CHAR(HEX2DEC(MID(A1,7,2)))),(CHAR(HEX2DEC(MID(A1, 9,2)))),(CHAR(HEX2DEC(MID(A1,11,2))))) -> #NAME? | M2: Hex | N2: 02 | O2: =IF(O3="","03",DEC2HEX(CODE(O3))) -> 38 | P2: =IF(P3="","03",DEC2HEX(CODE(P3))) -> 38 | Q2: =IF(Q3="","03",DEC2HEX(CODE(Q3))) -> 32 | R2: =IF(R3="","03",DEC2HEX(CODE(R3))) -> 61 | S2: =IF(S3="","03",DEC2HEX(CODE(S3))) -> 6E | T2: =IF(T3="ETX","03",DEC2HEX(CODE(T3))) -> 03 | U2: =IF(U3="ETX","03",DEC2HEX(CODE(U3))) -> #VALUE! | V2: =IF(V3="ETX","03",DEC2HEX(CODE(V3))) -> #VALUE! | W2: =IF(W3="ETX","03",DEC2HEX(CODE(W3))) -> #VALUE! | X2: =IF(X3="ETX","03",DEC2HEX(CODE(X3))) -> #VALUE! | Y2: =IF(Y3="ETX","03",DEC2HEX(CODE(Y3))) -> #VALUE! | Z2: =IF(Z3="ETX","03",DEC2HEX(CODE(Z3))) -> #VALUE! | AA2: =IF(AA3="ETX","03",DEC2HEX(CODE(AA3))) -> #VALUE! | ... AG2: =IF(AG3="ETX","03",DEC2HEX(CODE(AG3))) -> #VALUE!
A3: End of Text | B3: ETX | C3: 3 | D3: =HEX2DEC(C3) -> 3 | M3: Text | N3: STX | O3: 8 | P3: 8 | Q3: 2 | R3: a | S3: n | T3: ETX
A4: Character | B4: HEX | C4: DEC | E4: Character | F4: HEX | G4: DEC | I4: Character | J4: HEX | K4: DEC
A5: 0 | B5: =DEC2HEX(CODE(A5)) -> 30 | C5: =HEX2DEC(B5) -> 48 | E5: A | F5: =DEC2HEX(CODE(E5)) -> 41 | G5: =HEX2DEC(F5) -> 65 | I5: a | J5: =DEC2HEX(CODE(I5)) -> 61 | K5: =HEX2DEC(J5) -> 97 | M5: Hex | N5: 4e | O5: 41 | P5: 4d | Q5: 45
A6: 1 | B6: =DEC2HEX(CODE(A6)) -> 31 | C6: =HEX2DEC(B6) -> 49 | E6: B | F6: =DEC2HEX(CODE(E6)) -> 42 | G6: =HEX2DEC(F6) -> 66 | I6: b | J6: =DEC2HEX(CODE(I6)) -> 62 | K6: =HEX2DEC(J6) -> 98 | M6: Text | N6: =IF(N5="","",CHAR(HEX2DEC(MID(N5,1,2)))) -> N | O6: =IF(O5="","",CHAR(HEX2DEC(MID(O5,1,2)))) -> A | P6: =IF(P5="","",CHAR(HEX2DEC(MID(P5,1,2)))) -> M | Q6: =IF(Q5="","",CHAR(HEX2DEC(MID(Q5,1,2)))) -> E | R6: =IF(R5="","",CHAR(HEX2DEC(MID(R5,1,2)))) | S6: =IF(S5="","",CHAR(HEX2DEC(MID(S5,1,2)))) | T6: =IF(T5="","",CHAR(HEX2DEC(MID(T5,1,2)))) | U6: =IF(U5="","",CHAR(HEX2DEC(MID(U5,1,2)))) | ... AG6: =IF(AG5="","",CHAR(HEX2DEC(MID(AG5,1,2))))
A7: 2 | B7: =DEC2HEX(CODE(A7)) -> 32 | C7: =HEX2DEC(B7) -> 50 | E7: C | F7: =DEC2HEX(CODE(E7)) -> 43 | G7: =HEX2DEC(F7) -> 67 | I7: c | J7: =DEC2HEX(CODE(I7)) -> 63 | K7: =HEX2DEC(J7) -> 99
A8: 3 | B8: =DEC2HEX(CODE(A8)) -> 33 | C8: =HEX2DEC(B8) -> 51 | E8: D | F8: =DEC2HEX(CODE(E8)) -> 44 | G8: =HEX2DEC(F8) -> 68 | I8: d | J8: =DEC2HEX(CODE(I8)) -> 64 | K8: =HEX2DEC(J8) -> 100
A9: 4 | B9: =DEC2HEX(CODE(A9)) -> 34 | C9: =HEX2DEC(B9) -> 52 | E9: E | F9: =DEC2HEX(CODE(E9)) -> 45 | G9: =HEX2DEC(F9) -> 69 | I9: e | J9: =DEC2HEX(CODE(I9)) -> 65 | K9: =HEX2DEC(J9) -> 101
A10: 5 | B10: =DEC2HEX(CODE(A10)) -> 35 | C10: =HEX2DEC(B10) -> 53 | E10: F | F10: =DEC2HEX(CODE(E10)) -> 46 | G10: =HEX2DEC(F10) -> 70 | I10: f | J10: =DEC2HEX(CODE(I10)) -> 66 | K10: =HEX2DEC(J10) -> 102
A11: 6 | B11: =DEC2HEX(CODE(A11)) -> 36 | C11: =HEX2DEC(B11) -> 54 | E11: G | F11: =DEC2HEX(CODE(E11)) -> 47 | G11: =HEX2DEC(F11) -> 71 | I11: g | J11: =DEC2HEX(CODE(I11)) -> 67 | K11: =HEX2DEC(J11) -> 103
A12: 7 | B12: =DEC2HEX(CODE(A12)) -> 37 | C12: =HEX2DEC(B12) -> 55 | E12: H | F12: =DEC2HEX(CODE(E12)) -> 48 | G12: =HEX2DEC(F12) -> 72 | I12: h | J12: =DEC2HEX(CODE(I12)) -> 68 | K12: =HEX2DEC(J12) -> 104
A13: 8 | B13: =DEC2HEX(CODE(A13)) -> 38 | C13: =HEX2DEC(B13) -> 56 | E13: I | F13: =DEC2HEX(CODE(E13)) -> 49 | G13: =HEX2DEC(F13) -> 73 | I13: i | J13: =DEC2HEX(CODE(I13)) -> 69 | K13: =HEX2DEC(J13) -> 105
A14: 9 | B14: =DEC2HEX(CODE(A14)) -> 39 | C14: =HEX2DEC(B14) -> 57 | E14: J | F14: =DEC2HEX(CODE(E14)) -> 4A | G14: =HEX2DEC(F14) -> 74 | I14: j | J14: =DEC2HEX(CODE(I14)) -> 6A | K14: =HEX2DEC(J14) -> 106
A15: . | B15: =DEC2HEX(CODE(A15)) -> 2E | C15: =HEX2DEC(B15) -> 46 | E15: K | F15: =DEC2HEX(CODE(E15)) -> 4B | G15: =HEX2DEC(F15) -> 75 | I15: k | J15: =DEC2HEX(CODE(I15)) -> 6B | K15: =HEX2DEC(J15) -> 107
A16: \ | B16: =DEC2HEX(CODE(A16)) -> 5C | C16: =HEX2DEC(B16) -> 92 | E16: L | F16: =DEC2HEX(CODE(E16)) -> 4C | G16: =HEX2DEC(F16) -> 76 | I16: l | J16: =DEC2HEX(CODE(I16)) -> 6C | K16: =HEX2DEC(J16) -> 108
A17: ? | B17: =DEC2HEX(CODE(A17)) -> 3F | C17: =HEX2DEC(B17) -> 63 | E17: M | F17: =DEC2HEX(CODE(E17)) -> 4D | G17: =HEX2DEC(F17) -> 77 | I17: m | J17: =DEC2HEX(CODE(I17)) -> 6D | K17: =HEX2DEC(J17) -> 109
A18: < | B18: =DEC2HEX(CODE(A18)) -> 3C | C18: =HEX2DEC(B18) -> 60 | E18: N | F18: =DEC2HEX(CODE(E18)) -> 4E | G18: =HEX2DEC(F18) -> 78 | I18: n | J18: =DEC2HEX(CODE(I18)) -> 6E | K18: =HEX2DEC(J18) -> 110
A19: > | B19: =DEC2HEX(CODE(A19)) -> 3E | C19: =HEX2DEC(B19) -> 62 | E19: O | F19: =DEC2HEX(CODE(E19)) -> 4F | G19: =HEX2DEC(F19) -> 79 | I19: o | J19: =DEC2HEX(CODE(I19)) -> 6F | K19: =HEX2DEC(J19) -> 111
A20: ! | B20: =DEC2HEX(CODE(A20)) -> 21 | C20: =HEX2DEC(B20) -> 33 | E20: P | F20: =DEC2HEX(CODE(E20)) -> 50 | G20: =HEX2DEC(F20) -> 80 | I20: p | J20: =DEC2HEX(CODE(I20)) -> 70 | K20: =HEX2DEC(J20) -> 112
A21: @ | B21: =DEC2HEX(CODE(A21)) -> 40 | C21: =HEX2DEC(B21) -> 64 | E21: Q | F21: =DEC2HEX(CODE(E21)) -> 51 | G21: =HEX2DEC(F21) -> 81 | I21: q | J21: =DEC2HEX(CODE(I21)) -> 71 | K21: =HEX2DEC(J21) -> 113
A22: # | B22: =DEC2HEX(CODE(A22)) -> 23 | C22: =HEX2DEC(B22) -> 35 | E22: R | F22: =DEC2HEX(CODE(E22)) -> 52 | G22: =HEX2DEC(F22) -> 82 | I22: r | J22: =DEC2HEX(CODE(I22)) -> 72 | K22: =HEX2DEC(J22) -> 114
A23: $ | B23: =DEC2HEX(CODE(A23)) -> 24 | C23: =HEX2DEC(B23) -> 36 | E23: S | F23: =DEC2HEX(CODE(E23)) -> 53 | G23: =HEX2DEC(F23) -> 83 | I23: s | J23: =DEC2HEX(CODE(I23)) -> 73 | K23: =HEX2DEC(J23) -> 115
A24: % | B24: =DEC2HEX(CODE(A24)) -> 25 | C24: =HEX2DEC(B24) -> 37 | E24: T | F24: =DEC2HEX(CODE(E24)) -> 54 | G24: =HEX2DEC(F24) -> 84 | I24: t | J24: =DEC2HEX(CODE(I24)) -> 74 | K24: =HEX2DEC(J24) -> 116
A25: ^ | B25: =DEC2HEX(CODE(A25)) -> 5E | C25: =HEX2DEC(B25) -> 94 | E25: U | F25: =DEC2HEX(CODE(E25)) -> 55 | G25: =HEX2DEC(F25) -> 85 | I25: u | J25: =DEC2HEX(CODE(I25)) -> 75 | K25: =HEX2DEC(J25) -> 117
A26: * | B26: =DEC2HEX(CODE(A26)) -> 2A | C26: =HEX2DEC(B26) -> 42 | E26: V | F26: =DEC2HEX(CODE(E26)) -> 56 | G26: =HEX2DEC(F26) -> 86 | I26: v | J26: =DEC2HEX(CODE(I26)) -> 76 | K26: =HEX2DEC(J26) -> 118
... A30: + | B30: =DEC2HEX(CODE(A30)) -> 2B | C30: =HEX2DEC(B30) -> 43 | E30: Z | F30: =DEC2HEX(CODE(E30)) -> 5A | G30: =HEX2DEC(F30) -> 90 | I30: z | J30: =DEC2HEX(CODE(I30)) -> 7A | K30: =HEX2DEC(J30) -> 122
B31: =DEC2HEX(CODE(A31)) -> 20 | C31: =HEX2DEC(B31) -> 32
A52: a | B52: =DEC2HEX(CODE(A52)) -> 61 | C52: =HEX2DEC(B52) -> 97
A53: b | B53: =DEC2HEX(CODE(A53)) -> 62 | C53: =HEX2DEC(B53) -> 98
A54: c | B54: =DEC2HEX(CODE(A54)) -> 63 | C54: =HEX2DEC(B54) -> 99
A55: d | B55: =DEC2HEX(CODE(A55)) -> 64 | C55: =HEX2DEC(B55) -> 100
A56: e | B56: =DEC2HEX(CODE(A56)) -> 65 | C56: =HEX2DEC(B56) -> 101
A57: f | B57: =DEC2HEX(CODE(A57)) -> 66 | C57: =HEX2DEC(B57) -> 102
A58: g | B58: =DEC2HEX(CODE(A58)) -> 67 | C58: =HEX2DEC(B58) -> 103
A59: h | B59: =DEC2HEX(CODE(A59)) -> 68 | C59: =HEX2DEC(B59) -> 104
A60: i | B60: =DEC2HEX(CODE(A60)) -> 69 | C60: =HEX2DEC(B60) -> 105
A61: j | B61: =DEC2HEX(CODE(A61)) -> 6A | C61: =HEX2DEC(B61) -> 106
A62: k | B62: =DEC2HEX(CODE(A62)) -> 6B | C62: =HEX2DEC(B62) -> 107
A63: l | B63: =DEC2HEX(CODE(A63)) -> 6C | C63: =HEX2DEC(B63) -> 108
...

Sheet Param ID
M23: 42

Sheet SPE Cycles
B1: ATEQ Premier F (520F, F5) Pressure Decay | C1: ATEQ Premier MF (520MF, MF5) Diff Mass Flow
B2: Validated = Green | C2: Validated = Green
A3: 1.2. SPECIAL CYCLE BIT TABLE
A4: ATR learning. | B4: 1 | C4: 1
A5: Check calibration. | B5: 2
A6: Auto – test. | B6: 3
A7: Calibration. | B7: 4 | C7: 4
A8: Verification calibration. | B8: 5 | C8: 5
A9: ATR + calibration. | B9: 6 | C9: 6
A10: Auto zero piezo | B10: 7 | C10: 7
A11: Auto zero piezo | B11: 8 | C11: 8
A12: Auxiliary regulator. | B12: 9 | C12: 9
A13: Regulator Adjust | B13: 10 | C13: 10
A14: Infinite fill. | B14: 11 | C14: 11
A15: Volume calculation. | B15: 12 | C15: 12
A16: No special cycle. | B16: 13 | C16: 13
A17: Sealed PASS Part Learn | B17: 16 | C17: 16
A18: Sealed FAIL Part Learn | B18: 17 | C18: 17
A19: 24 Save parameters in flash | B19: 24 | C19: 24

Sheet Units Codes

Sheet Alarm Codes
A1: Alarm Codes

Sheet Steps Table

Sheet Write Parameters
F1: =MOD(HEX2DEC(CONCATENATE(F7,G7,H7,I7))+2^31,2^32)-2^31 -> -402456576
